<?xml version="1.0"?>
<robot name="Anakleto">
    <material name="red">
        <color rgba="0.9 0.2 0.0 1.0"/>
    </material>
    <material name="green">
        <color rgba="0.0 0.9 0.1 1.0"/>
    </material>
    <material name="blue">
        <color rgba="0.1 0.0 1.0 1.0"/>
    </material>
    <material name="orange">
        <color rgba="0.9 0.5 0.1 1.0"/>
    </material>
    <material name="black">
        <color rgba="0.0 0.0 0.0 0.5"/>
    </material>
    <material name="white">
        <color rgba="0.7 0.7 0.7 1.0"/>
    </material>
    <material name="nocolor">
        <color rgba="0.0 0.0 0.0 0.0"/>
    </material>
    <arg name="pi" value="3.14159265359"/>
    <arg name="limit" value="pi/2"/>
    
    
    <link name="world">
        <visual>
            <geometry>
                <cylinder radius="5" length="0.001"/>
            </geometry>
            <material name="black"/>
            <origin xyz="0.0 0.0 0.0005" rpy="0.0 0.0 0.0"/>
            <collision>
            <geometry>
               <cylinder radius="5" length="0.001"/>
            </geometry>
            <origin xyz="0.0 0.0 0.0005" rpy="0.0 0.0 0.0"/>
        </collision>
        </visual>
    </link>
    <joint name="jointbase" type="fixed">
        <parent link="world"/>
        <child link="base_link"/>
        <origin xyz="0.0 0.0 0.0" rpy="0.0 0.0 0.0"/>
    </joint>
    <link name="base_link">
        <visual>
            <geometry>
              <mesh filename="package://tutorial_urdf/meshes/robots/arm/base_arm.stl" scale="0.01 0.01 0.01"/>
            </geometry>
            <material name="white"/>
            <origin xyz="-1.28 -1.28 0.0" rpy="0.0 0.0 0.0"/>
        </visual>
        <collision>
            <geometry>
                <mesh filename="package://tutorial_urdf/meshes/robots/arm/base_arm.stl" scale="0.01 0.01 0.01"/>
            </geometry>
            <origin xyz="-1.28 -1.28 0.0" rpy="0.0 0.0 0.0"/>
        </collision>
     </link>

    <joint name="joint_aux1" type="fixed">
        <parent link="base_link"/>
        <child link="aux_link1"/>
        <origin xyz="0.0 0.0 0.35" rpy="0.0 0.0 0.0"/>
    </joint>

    <link name="aux_link1">
        <visual>
            <geometry>
                <cylinder radius="0.1" length="0.01"/>
            </geometry>
            <material name="nocolor"/>
            <origin xyz="0.0 0.0 0.005" rpy="0.0 0.0 0.0"/>
        </visual>
    </link>


    <joint name="joint_0" type="revolute">
        <parent link="aux_link1"/>
        <child link="b1_link"/>
      <origin xyz="0.0 0.0 0.0" rpy="0.0 0.0 0.0"/>
        <axis xyz="0.0 0.0 1.0"/>
        <limit lower="-1.57" upper="1.57" effort="0.39" velocity="1.0"/>
    </joint>

    <link name="b1_link">
        <visual>
            <geometry>
                <mesh filename="package://tutorial_urdf/meshes/robots/arm/arm_link1.stl" scale="0.01 0.01 0.01"/>
            </geometry>
            <material name="black"/>
            <origin xyz="-1.28 -1.28 -0.35" rpy="0.0 0.0 0.0"/>
        </visual>
        <collision>
            <geometry>
                <mesh filename="package://tutorial_urdf/meshes/robots/arm/arm_link1.stl" scale="0.01 0.01 0.01"/>
            </geometry>
                <origin xyz="-1.28 -1.28 -0.35" rpy="0.0 0.0 0.0"/>
        </collision>
        <inertial>
            <mass value="0.06"/>
            <inertia ixx="0.0770" ixy="0.0" ixz="0.0" iyy="0.1159" iyz="0.0" izz="0.0780"/>
        </inertial>
    </link>

    <joint name="joint_aux2" type="fixed">
        <parent link="b1_link"/>
        <child link="aux_link2"/>
        <origin xyz="0.0 0.0 0.235" rpy="0.0 0.0 0.0"/>
    </joint>

    <link name="aux_link2">
        <visual>
            <geometry>
                <cylinder radius="0.1" length="0.01"/>
            </geometry>
            <material name="nocolor"/>
            <origin xyz="0.0 0.0 0.005" rpy="0.0 0.0 0.0"/>
        </visual>
    </link>

    <joint name="joint_1" type="revolute">
        <parent link="aux_link2"/>
        <child link="b2_link"/>
       <origin xyz="0.0 0.0 0.0" rpy="0.0 0.0 0.0"/>
        <axis xyz="1.0 0.0 0.0"/>
       <limit lower="-1.57" upper="1.57" effort="0.39" velocity="1.0"/>
    </joint>

    <link name="b2_link">
        <visual>
            <geometry>
                <mesh filename="package://tutorial_urdf/meshes/robots/arm/arm_link2.stl" scale="0.01 0.01 0.01"/>
            </geometry>
            <material name="red"/>
            <origin xyz="-1.28 -1.28 -0.6" rpy="0.0 0.0 0.0"/>
                
        </visual>
        <collision>
            <geometry>
                <mesh filename="package://tutorial_urdf/meshes/robots/arm/arm_link2.stl" scale="0.01 0.01 0.01"/>
            </geometry>
            <origin xyz="-1.28 -1.28 -0.6" rpy="0.0 0.0 0.0"/>
        </collision>
        <inertial>
            <mass value="0.06"/>
            <inertia ixx="0.3006" ixy="0.0" ixz="0.0" iyy="0.3313" iyz="0.0" izz="0.0932"/>
        </inertial>
    </link>
    
    <joint name="joint_aux3" type="fixed">
        <parent link="b2_link"/>
        <child link="aux_link3"/>
        <origin xyz="0.0 0.0 0.52" rpy="0.0 0.0 0.0"/>
    </joint>

    <link name="aux_link3">
        <visual>
            <geometry>
                <cylinder radius="0.1" length="0.01"/>
            </geometry>
            <material name="nocolor"/>
             <origin xyz="0.0 0.0 0.005" rpy="0.0 0.0 0.0"/>
        </visual>
    </link>


    <joint name="joint_2" type="revolute">
        <parent link="aux_link3"/>
        <child link="b3_link"/>
        <origin xyz="0.0 0.0 0.0" rpy="0.0 0.0 0.0"/>
        <axis xyz="1.0 0.0 0.0"/>
       <limit lower="-1.57" upper="1.57" effort="0.39" velocity="1.0"/>
    </joint>

    <link name="b3_link">
        <visual>
            <geometry>
                <mesh filename="package://tutorial_urdf/meshes/robots/arm/arm_link3.stl" scale="0.01 0.01 0.01"/>
            </geometry>
            <material name="green"/>
            <origin xyz="-1.28 -1.28 -1.125" rpy="0.0 0.0 0.0"/>
        </visual>
        <collision>
            <geometry>
                <mesh filename="package://tutorial_urdf/meshes/robots/arm/arm_link3.stl" scale="0.01 0.01 0.01"/>
            </geometry>
            <origin xyz="-1.28 -1.28 -1.125" rpy="0.0 0.0 0.0"/>
        </collision>
        <inertial>
            <mass value="0.06"/>
            <inertia ixx="1.0" ixy="0.1076" ixz="0.0" iyy="0.1198" iyz="0.0" izz="0.07476"/>
        </inertial>
    </link>

    <joint name="joint_aux4" type="fixed">
        <parent link="b3_link"/>
        <child link="aux_link4"/>
        <origin xyz="0.0 0.0 0.43" rpy="0.0 0.0 0.0"/>
    </joint>

    <link name="aux_link4">
        <visual>
            <geometry>
                <cylinder radius="0.1" length="0.01"/>
            </geometry>
            <material name="nocolor"/>
             <origin xyz="0.0 0.0 0.005" rpy="0.0 0.0 0.0"/>
        </visual>
    </link>

    <joint name="joint_3" type="revolute">
        <parent link="aux_link4"/>
        <child link="b4_link"/>
        <origin xyz="0.0 0.0 0.0" rpy="0.0 0.0 0.0"/>
        <axis xyz="0.0 0.0 1.0"/>
        <limit lower="-1.57" upper="1.57" effort="0.39" velocity="1.0"/>
    </joint>

    <link name="b4_link">
      <visual>
            <geometry>
                <mesh filename="package://tutorial_urdf/meshes/robots/arm/arm_link4.stl" scale="0.01 0.01 0.01"/>
            </geometry>
            <material name="red"/>
            <origin xyz="-1.28 -1.28 -1.55" rpy="0.0 0.0 0.0"/>
        </visual>
        <collision>
            <geometry>
                    <mesh filename="package://tutorial_urdf/meshes/robots/arm/arm_link4.stl" scale="0.01 0.01 0.01"/>
            </geometry>
                <origin xyz="-1.28 -1.28 -1.55" rpy="0.0 0.0 0.0"/>
        </collision>
        <inertial>
            <mass value="0.06"/>
            <inertia ixx="0.2659" ixy="0.0" ixz="0.0" iyy="0.0994" iyz="0.0" izz="0.2903"/>
        </inertial>
    </link>

    <joint name="joint_aux5" type="fixed">
        <parent link="b4_link"/>
        <child link="aux_link5"/>
        <origin xyz="0.0 -0.45 0.0" rpy="0.0 0.0 0.0"/>
    </joint>

    <link name="aux_link5">
        <visual>
            <geometry>
                <cylinder radius="0.1" length="0.01"/>
            </geometry>
            <material name="nocolor"/>
            <origin xyz="0.0 0.0 0.005" rpy="0.0 0.0 0.0"/>
        </visual>
    </link>

    <joint name="joint_4" type="revolute">
        <parent link="aux_link5"/>
        <child link="b5_link"/>
        <origin xyz="0.0 0.0 0.0" rpy="0.0 0.0 0.0"/>
        <axis xyz="1.0 0.0 0.0"/>
        <limit lower="-1.57" upper="1.57" effort="0.39" velocity="1.0"/>
    </joint>

    <link name="b5_link">
       <visual>
            <geometry>
                <mesh filename="package://tutorial_urdf/meshes/robots/arm/arm_link5.stl" scale="0.01 0.01 0.01"/>
            </geometry>
            <material name="blue"/>
            <origin xyz="-1.28 -0.84 -1.55" rpy="0.0 0.0 0.0"/>
        </visual>
        <collision>
            <geometry>
                    <mesh filename="package://tutorial_urdf/meshes/robots/arm/arm_link5.stl" scale="0.01 0.01 0.01"/>
            </geometry>
           <origin xyz="-1.28 -0.84 -1.55" rpy="0.0 0.0 0.0"/>
        </collision>
        <inertial>
            <mass value="0.06"/>
            <inertia ixx="0.2966" ixy="0.0" ixz="0.0" iyy="0.0932" iyz="0.0" izz="0.3273"/>
        </inertial>
    </link>

    <joint name="joint_aux6" type="fixed">
        <parent link="b5_link"/>
        <child link="aux_link6"/>
        <origin xyz="0.0 -0.55 0.0" rpy="0.0 0.0 0.0"/>
    </joint>

    <link name="aux_link6">
        <visual>
            <geometry>
                <cylinder radius="0.1" length="0.01"/>
            </geometry>
            <material name="nocolor"/>
             <origin xyz="0.0 0.0 0.005" rpy="0.0 0.0 0.0"/>
        </visual>
    </link>

    <joint name="joint_5" type="revolute">
        <parent link="aux_link6"/>
        <child link="b6_link"/>
        <origin xyz="0.0 0.0 0.0" rpy="0.0 0.0 0.0"/>
        <axis xyz="1.0 0.0 0.0"/>
        <limit lower="-1.57" upper="1.57" effort="0.39" velocity="1.0"/>
    </joint>

    <link name="b6_link">
       <visual>
            <geometry>
                <mesh filename="package://tutorial_urdf/meshes/robots/arm/arm_link6.stl" scale="0.01 0.01 0.01"/>
            </geometry>
            <material name="green"/>
            <origin xyz="-1.28 -0.305 -1.55" rpy="0.0 0.0 0.0"/>
        </visual>
        <collision>
            <geometry>
                <mesh filename="package://tutorial_urdf/meshes/robots/arm/arm_link6.stl" scale="0.01 0.01 0.01"/>
            </geometry>
            <origin xyz="-1.28 -0.305 -1.55" rpy="0.0 0.0 0.0"/>
        </collision>
        <inertial>
            <mass value="0.09"/>
            <inertia ixx="0.5962" ixy="0.0" ixz="0.0" iyy="0.1257" iyz="0.0" izz="0.6081"/>
        </inertial>
    </link>
</robot>