<?xml version="1.0" ?>
<!-- =================================================================================== -->
<!-- |    This document was autogenerated by xacro from arm20.urdf.xacro               | -->
<!-- |    EDITING THIS FILE BY HAND IS NOT RECOMMENDED                                 | -->
<!-- =================================================================================== -->
<robot name="arm20">
  <material name="red">
    <color rgba="0.9 0.2 0.0 1.0"/>
  </material>
  <material name="green">
    <color rgba="0.0 0.9 0.1 1.0"/>
  </material>
  <material name="blue">
    <color rgba="0.1 0.0 1.0 1.0"/>
  </material>
  <material name="orange">
    <color rgba="0.9 0.5 0.1 1.0"/>
  </material>
  <material name="black">
    <color rgba="0.0 0.0 0.0 0.5"/>
  </material>
  <material name="white">
    <color rgba="0.7 0.7 0.7 1.0"/>
  </material>
  <material name="nocolor">
    <color rgba="0.0 0.0 0.0 0.0"/>
  </material>
  <!-- ros_control plugin -->
  <gazebo>
    <plugin filename="libgazebo_ros_control.so" name="gazebo_ros_control">
      <robotNamespace>/arm20</robotNamespace>
      <robotSimType>gazebo_ros_control/DefaultRobotHWSim</robotSimType>
      <legacyModeNS>true</legacyModeNS>
    </plugin>
  </gazebo>
  <!-- world -->
  <gazebo reference="world">
    <!--<material>Gazebo/Orange</material>-->
  </gazebo>
  <!-- Link0 -->
  <gazebo reference="base_link">
    <!--<material>Gazebo/Orange</material>-->
  </gazebo>
  <!-- Link1 -->
  <gazebo reference="link_1">
    <mu1>0.2</mu1>
    <mu2>0.2</mu2>
    <!--<material>Gazebo/Orange</material>-->
  </gazebo>
  <!-- aux_Link1 -->
  <gazebo reference="aux_link1">
    <!--<material>Gazebo/Orange</material>-->
  </gazebo>
  <!-- Link2 -->
  <gazebo reference="link_2">
    <mu1>0.2</mu1>
    <mu2>0.2</mu2>
    <!--<material>Gazebo/Orange</material>-->
  </gazebo>
  <!-- aux_Link2 -->
  <gazebo reference="aux_link2">
    <!--<material>Gazebo/Orange</material>-->
  </gazebo>
  <!-- Link3 -->
  <gazebo reference="link_3">
    <mu1>0.2</mu1>
    <mu2>0.2</mu2>
    <!--<material>Gazebo/Orange</material>-->
  </gazebo>
  <!-- aux_Link3 -->
  <gazebo reference="aux_link3">
    <!--<material>Gazebo/Orange</material>-->
  </gazebo>
  <!-- Link4 -->
  <gazebo reference="link_4">
    <mu1>0.2</mu1>
    <mu2>0.2</mu2>
    <!--<material>Gazebo/Orange</material>-->
  </gazebo>
  <!-- aux_Link4 -->
  <gazebo reference="aux_link4">
    <!--<material>Gazebo/Orange</material>-->
  </gazebo>
  <!-- Link5 -->
  <gazebo reference="link_5">
    <mu1>0.2</mu1>
    <mu2>0.2</mu2>
    <!--<material>Gazebo/Orange</material>-->
  </gazebo>
  <!-- aux_Link5 -->
  <gazebo reference="aux_link5">
    <!--<material>Gazebo/Orange</material>-->
  </gazebo>
  <!-- Link6 -->
  <gazebo reference="link_6">
    <mu1>0.2</mu1>
    <mu2>0.2</mu2>
    <!--<material>Gazebo/Orange</material>-->
  </gazebo>
  <!-- aux_Link6 -->
  <gazebo reference="aux_link6">
    <!--<material>Gazebo/Orange</material>-->
  </gazebo>
  <link name="world"/>
  <joint name="fixed" type="fixed">
    <parent link="world"/>
    <child link="base_link"/>
  </joint>
  <link name="base_link">
    <inertial>
      <origin rpy="0.0 0.0 0.0" xyz="-1.28 -1.28 0.0"/>
      <mass value="1.0"/>
      <inertia ixx="1.0" ixy="0.0" ixz="0.0" iyy="1.0" iyz="0.0" izz="1.0"/>
    </inertial>
    <visual>
      <origin rpy="0.0 0.0 0.0" xyz="-1.28 -1.28 0.0"/>
      <geometry>
        <mesh filename="package://tutorial_urdf/meshes/robots/arm/base_arm.stl" scale="0.01 0.01 0.01"/>
      </geometry>
      <material name="white"/>
    </visual>
    <collision>
      <origin rpy="0.0 0.0 0.0" xyz="-1.28 -1.28 0.0"/>
      <geometry>
        <mesh filename="package://tutorial_urdf/meshes/robots/arm/base_arm.stl" scale="0.01 0.01 0.01"/>
      </geometry>
    </collision>
  </link>
  <joint name="joint_aux1" type="fixed">
    <origin rpy="0.0 0.0 0.0" xyz="0.0 0.0 0.35"/>
    <parent link="base_link"/>
    <child link="aux_link1"/>
  </joint>
  <link name="aux_link1">
    <visual>
      <geometry>
        <cylinder length="0.001" radius="0.01"/>
      </geometry>
      <material name="nocolor"/>
      <origin rpy="0.0 0.0 0.0" xyz="0.0 0.0 0.0005"/>
    </visual>
  </link>
  <joint name="joint_1" type="revolute">
    <origin rpy="0.0 0.0 0.0" xyz="0.0 0.0 0.0"/>
    <parent link="aux_link1"/>
    <child link="link_1"/>
    <axis xyz="0.0 0.0 1.0"/>
    <limit effort="0.39" lower="-1.5707963267948966" upper="1.5707963267948966" velocity="1.0"/>
  </joint>
  <link name="link_1">
    <inertial>
      <origin rpy="0.0 0.0 0.0" xyz="-1.28 -1.28 -0.35"/>
      <mass value="0.06"/>
      <inertia ixx="0.077" ixy="0.0" ixz="0.0" iyy="0.1159" iyz="0.0" izz="0.078"/>
    </inertial>
    <visual>
      <origin rpy="0.0 0.0 0.0" xyz="-1.28 -1.28 -0.35"/>
      <geometry>
        <mesh filename="package://tutorial_urdf/meshes/robots/arm/arm_link1.stl" scale="0.01 0.01 0.01"/>
      </geometry>
      <material name="green"/>
    </visual>
    <collision>
      <origin rpy="0.0 0.0 0.0" xyz="-1.28 -1.28 -0.35"/>
      <geometry>
        <mesh filename="package://tutorial_urdf/meshes/robots/arm/arm_link1.stl" scale="0.01 0.01 0.01"/>
      </geometry>
    </collision>
  </link>
  <transmission name="tran_1">
    <type>transmission_interface/SimpleTransmission</type>
    <joint name="joint_1">
      <hardwareInterface>hardware_interface/EffortJointInterface</hardwareInterface>
    </joint>
    <actuator name="motor_1">
      <hardwareInterface>hardware_interface/EffortJointInterface</hardwareInterface>
      <mechanicalReduction>238</mechanicalReduction>
    </actuator>
  </transmission>
  <joint name="joint_aux2" type="fixed">
    <origin rpy="0.0 0.0 0.0" xyz="0.0 0.0 0.235"/>
    <parent link="link_1"/>
    <child link="aux_link2"/>
  </joint>
  <link name="aux_link2">
    <visual>
      <geometry>
        <cylinder length="0.001" radius="0.01"/>
      </geometry>
      <material name="nocolor"/>
      <origin rpy="0.0 0.0 0.0" xyz="0.0 0.0 0.0005"/>
    </visual>
  </link>
  <joint name="joint_2" type="revolute">
    <origin rpy="0.0 0.0 0.0" xyz="0.0 0.0 0.0"/>
    <parent link="aux_link2"/>
    <child link="link_2"/>
    <axis xyz="1.0 0.0 0.0"/>
    <limit effort="0.39" lower="-1.5707963267948966" upper="1.5707963267948966" velocity="1.0"/>
  </joint>
  <link name="link_2">
    <inertial>
      <origin rpy="0.0 0.0 0.0" xyz="-1.28 -1.28 -0.6"/>
      <mass value="0.06"/>
      <inertia ixx="0.3006" ixy="0.0" ixz="0.0" iyy="0.33130000000000004" iyz="0.0" izz="0.0932"/>
    </inertial>
    <visual>
      <origin rpy="0.0 0.0 0.0" xyz="-1.28 -1.28 -0.6"/>
      <geometry>
        <mesh filename="package://tutorial_urdf/meshes/robots/arm/arm_link2.stl" scale="0.01 0.01 0.01"/>
      </geometry>
      <material name="blue"/>
    </visual>
    <collision>
      <origin rpy="0.0 0.0 0.0" xyz="-1.28 -1.28 -0.6"/>
      <geometry>
        <mesh filename="package://tutorial_urdf/meshes/robots/arm/arm_link2.stl" scale="0.01 0.01 0.01"/>
      </geometry>
    </collision>
  </link>
  <transmission name="tran_2">
    <type>transmission_interface/SimpleTransmission</type>
    <joint name="joint_2">
      <hardwareInterface>hardware_interface/EffortJointInterface</hardwareInterface>
    </joint>
    <actuator name="motor_2">
      <hardwareInterface>hardware_interface/EffortJointInterface</hardwareInterface>
      <mechanicalReduction>238</mechanicalReduction>
    </actuator>
  </transmission>
  <joint name="joint_aux3" type="fixed">
    <origin rpy="0.0 0.0 0.0" xyz="0.0 0.0 0.52"/>
    <parent link="link_2"/>
    <child link="aux_link3"/>
  </joint>
  <link name="aux_link3">
    <visual>
      <geometry>
        <cylinder length="0.001" radius="0.01"/>
      </geometry>
      <material name="nocolor"/>
      <origin rpy="0.0 0.0 0.0" xyz="0.0 0.0 0.0005"/>
    </visual>
  </link>
  <joint name="joint_3" type="revolute">
    <origin rpy="0.0 0.0 0.0" xyz="0.0 0.0 0.0"/>
    <parent link="aux_link3"/>
    <child link="link_3"/>
    <axis xyz="1.0 0.0 0.0"/>
    <limit effort="0.39" lower="-1.5707963267948966" upper="1.5707963267948966" velocity="1.0"/>
  </joint>
  <link name="link_3">
    <inertial>
      <origin rpy="0.0 0.0 0.0" xyz="-1.28 -1.28 -1.125"/>
      <mass value="0.06"/>
      <inertia ixx="0.1076" ixy="0.0" ixz="0.0" iyy="0.1198" iyz="0.0" izz="0.0747"/>
    </inertial>
    <visual>
      <origin rpy="0.0 0.0 0.0" xyz="-1.28 -1.28 -1.125"/>
      <geometry>
        <mesh filename="package://tutorial_urdf/meshes/robots/arm/arm_link3.stl" scale="0.01 0.01 0.01"/>
      </geometry>
      <material name="red"/>
    </visual>
    <collision>
      <origin rpy="0.0 0.0 0.0" xyz="-1.28 -1.28 -1.125"/>
      <geometry>
        <mesh filename="package://tutorial_urdf/meshes/robots/arm/arm_link3.stl" scale="0.01 0.01 0.01"/>
      </geometry>
    </collision>
  </link>
  <transmission name="tran_3">
    <type>transmission_interface/SimpleTransmission</type>
    <joint name="joint_3">
      <hardwareInterface>hardware_interface/EffortJointInterface</hardwareInterface>
    </joint>
    <actuator name="motor_3">
      <hardwareInterface>hardware_interface/EffortJointInterface</hardwareInterface>
      <mechanicalReduction>238</mechanicalReduction>
    </actuator>
  </transmission>
  <joint name="joint_aux4" type="fixed">
    <origin rpy="0.0 0.0 0.0" xyz="0.0 0.0 0.43"/>
    <parent link="link_3"/>
    <child link="aux_link4"/>
  </joint>
  <link name="aux_link4">
    <visual>
      <geometry>
        <cylinder length="0.001" radius="0.01"/>
      </geometry>
      <material name="nocolor"/>
      <origin rpy="0.0 0.0 0.0" xyz="0.0 0.0 0.0005"/>
    </visual>
  </link>
  <joint name="joint_4" type="revolute">
    <origin rpy="0.0 0.0 0.0" xyz="0.0 0.0 0.0"/>
    <parent link="aux_link4"/>
    <child link="link_4"/>
    <axis xyz="0.0 0.0 1.0"/>
    <limit effort="0.39" lower="-1.5707963267948966" upper="1.5707963267948966" velocity="1.0"/>
  </joint>
  <link name="link_4">
    <inertial>
      <origin rpy="0.0 0.0 0.0" xyz="-1.28 -1.28 -1.55"/>
      <mass value="0.06"/>
      <inertia ixx="0.2659" ixy="0.0" ixz="0.0" iyy="0.09939999999999999" iyz="0.0" izz="0.2903"/>
    </inertial>
    <visual>
      <origin rpy="0.0 0.0 0.0" xyz="-1.28 -1.28 -1.55"/>
      <geometry>
        <mesh filename="package://tutorial_urdf/meshes/robots/arm/arm_link4.stl" scale="0.01 0.01 0.01"/>
      </geometry>
      <material name="white"/>
    </visual>
    <collision>
      <origin rpy="0.0 0.0 0.0" xyz="-1.28 -1.28 -1.55"/>
      <geometry>
        <mesh filename="package://tutorial_urdf/meshes/robots/arm/arm_link4.stl" scale="0.01 0.01 0.01"/>
      </geometry>
    </collision>
  </link>
  <transmission name="tran_4">
    <type>transmission_interface/SimpleTransmission</type>
    <joint name="joint_4">
      <hardwareInterface>hardware_interface/EffortJointInterface</hardwareInterface>
    </joint>
    <actuator name="motor_4">
      <hardwareInterface>hardware_interface/EffortJointInterface</hardwareInterface>
      <mechanicalReduction>238</mechanicalReduction>
    </actuator>
  </transmission>
  <joint name="joint_aux5" type="fixed">
    <origin rpy="0.0 0.0 0.0" xyz="0.0 -0.45 0.0"/>
    <parent link="link_4"/>
    <child link="aux_link5"/>
  </joint>
  <link name="aux_link5">
    <visual>
      <geometry>
        <cylinder length="0.001" radius="0.01"/>
      </geometry>
      <material name="nocolor"/>
      <origin rpy="0.0 0.0 0.0" xyz="0.0 0.0 0.0005"/>
    </visual>
  </link>
  <joint name="joint_5" type="revolute">
    <origin rpy="0.0 0.0 0.0" xyz="0.0 0.0 0.0"/>
    <parent link="aux_link5"/>
    <child link="link_5"/>
    <axis xyz="1.0 0.0 0.0"/>
    <limit effort="0.39" lower="-1.5707963267948966" upper="1.5707963267948966" velocity="1.0"/>
  </joint>
  <link name="link_5">
    <inertial>
      <origin rpy="0.0 0.0 0.0" xyz="-1.28 -0.84 -1.55"/>
      <mass value="0.06"/>
      <inertia ixx="0.2966" ixy="0.0" ixz="0.0" iyy="0.0932" iyz="0.0" izz="0.3273"/>
    </inertial>
    <visual>
      <origin rpy="0.0 0.0 0.0" xyz="-1.28 -0.84 -1.55"/>
      <geometry>
        <mesh filename="package://tutorial_urdf/meshes/robots/arm/arm_link5.stl" scale="0.01 0.01 0.01"/>
      </geometry>
      <material name="green"/>
    </visual>
    <collision>
      <origin rpy="0.0 0.0 0.0" xyz="-1.28 -0.84 -1.55"/>
      <geometry>
        <mesh filename="package://tutorial_urdf/meshes/robots/arm/arm_link5.stl" scale="0.01 0.01 0.01"/>
      </geometry>
    </collision>
  </link>
  <transmission name="tran_5">
    <type>transmission_interface/SimpleTransmission</type>
    <joint name="joint_5">
      <hardwareInterface>hardware_interface/EffortJointInterface</hardwareInterface>
    </joint>
    <actuator name="motor_5">
      <hardwareInterface>hardware_interface/EffortJointInterface</hardwareInterface>
      <mechanicalReduction>238</mechanicalReduction>
    </actuator>
  </transmission>
  <joint name="joint_aux6" type="fixed">
    <origin rpy="0.0 0.0 0.0" xyz="0.0 -0.55 0.0"/>
    <parent link="link_5"/>
    <child link="aux_link6"/>
  </joint>
  <link name="aux_link6">
    <visual>
      <geometry>
        <cylinder length="0.001" radius="0.01"/>
      </geometry>
      <material name="nocolor"/>
      <origin rpy="0.0 0.0 0.0" xyz="0.0 0.0 0.0005"/>
    </visual>
  </link>
  <joint name="joint_6" type="revolute">
    <origin rpy="0.0 0.0 0.0" xyz="0.0 0.0 0.0"/>
    <parent link="aux_link6"/>
    <child link="link_6"/>
    <axis xyz="1.0 0.0 0.0"/>
    <limit effort="0.39" lower="-1.5707963267948966" upper="1.5707963267948966" velocity="1.0"/>
  </joint>
  <link name="link_6">
    <inertial>
      <origin rpy="0.0 0.0 0.0" xyz="-1.28 -0.305 -1.55"/>
      <mass value="0.09"/>
      <inertia ixx="0.5962" ixy="0.0" ixz="0.0" iyy="0.1257" iyz="0.0" izz="0.6081"/>
    </inertial>
    <visual>
      <origin rpy="0.0 0.0 0.0" xyz="-1.28 -0.305 -1.55"/>
      <geometry>
        <mesh filename="package://tutorial_urdf/meshes/robots/arm/arm_link6.stl" scale="0.01 0.01 0.01"/>
      </geometry>
      <material name="blue"/>
    </visual>
    <collision>
      <origin rpy="0.0 0.0 0.0" xyz="-1.28 -0.305 -1.55"/>
      <geometry>
        <mesh filename="package://tutorial_urdf/meshes/robots/arm/arm_link6.stl" scale="0.01 0.01 0.01"/>
      </geometry>
    </collision>
  </link>
  <transmission name="tran_6">
    <type>transmission_interface/SimpleTransmission</type>
    <joint name="joint_6">
      <hardwareInterface>hardware_interface/EffortJointInterface</hardwareInterface>
    </joint>
    <actuator name="motor_6">
      <hardwareInterface>hardware_interface/EffortJointInterface</hardwareInterface>
      <mechanicalReduction>238</mechanicalReduction>
    </actuator>
  </transmission>
</robot>
