<?xml version="1.0"?>
<robot xmlns:xacro="http://www.ros.org/wiki/xacro" name="arm20">
  <xacro:property name="PI" value="3.1415926535897931"/>
  <xacro:property name="mass" value="0.06" /> 
  <xacro:property name="low_limit" value="${-pi/2}"/>
  <xacro:property name="up_limit" value="${pi/2}" />
  <xacro:property name="effort_value" value="0.39" />
  <xacro:property name="speed_value" value="1.0" />
  <xacro:property name="scale" value="100.0" />
  <xacro:property name="x" value="${-128/scale}" />
  <xacro:property name="y" value="${-128/scale}" />
  <xacro:property name="origin_base_xyz" value="${x} ${y} 0.0"/>
  <xacro:property name="origin_link1_xyz" value="${x} ${y} ${-35/scale}"/>
  <xacro:property name="origin_link2_xyz" value="${x} ${y} ${-60/scale}"/>
  <xacro:property name="origin_link3_xyz" value="${x} ${y} ${-112.5/scale}"/>
  <xacro:property name="origin_link4_xyz" value="${x} ${y} ${-155/scale}"/>
  <xacro:property name="origin_link5_xyz" value="${x} ${-84/scale} ${-155/scale}"/>
  <xacro:property name="origin_link6_xyz" value="${x} ${-30.5/scale} ${-155/scale}"/>
  <xacro:property name="joint1_xyz" value="0.0 0.0 ${35/scale}"/>
  <xacro:property name="joint2_xyz" value="0.0 0.0 ${23.5/scale}"/>
  <xacro:property name="joint3_xyz" value="0.0 0.0 ${52/scale}"/>
  <xacro:property name="joint4_xyz" value="0.0 0.0 ${43/scale}"/>
  <xacro:property name="joint5_xyz" value="0.0 ${-45/scale} 0.0"/>
  <xacro:property name="joint6_xyz" value="0.0 ${-55/scale} 0.0"/>
  
  <material name="red">
        <color rgba="0.9 0.2 0.0 1.0"/>
  </material>
  <material name="green">
        <color rgba="0.0 0.9 0.1 1.0"/>
  </material>
  <material name="blue">
        <color rgba="0.1 0.0 1.0 1.0"/>
  </material>
  <material name="orange">
        <color rgba="0.9 0.5 0.1 1.0"/>
  </material>
  <material name="black">
        <color rgba="0.0 0.0 0.0 0.5"/>
  </material>
  <material name="white">
        <color rgba="0.7 0.7 0.7 1.0"/>
  </material>
  <material name="nocolor">
        <color rgba="0.0 0.0 0.0 0.0"/>
  </material>

 <!-- Import all Gazebo-customization elements, including Gazebo colors -->
  <xacro:include filename="$(find arm20_description)/urdf/arm20.gazebo"/>

  <xacro:macro name="mesh_link" params="suffix  parent_link origin_xyz Joint_xyz meshfile meshscale mass ixx iyy izz Axis color">
        <joint name="joint_aux${suffix}" type="fixed">
            <origin xyz="${Joint_xyz}" rpy="0.0 0.0 0.0"/>
            <parent link="${parent_link}"/>
            <child link="aux_link${suffix}"/>
        </joint>
        <link name="aux_link${suffix}">
             <inertial>
               <origin xyz="0.0 0.0 0.0005" rpy="0.0 0.0 0.0"/>
                <mass value="1.05"/>
                <inertia ixx="1.01" ixy="0.0" ixz="0.0" iyy="1.01" iyz="0.0" izz="1.01"/>
            </inertial>
            <visual>
                <geometry>
                    <cylinder radius="0.01" length="0.001"/>
                </geometry>
                <material name="nocolor"/>
                <origin xyz="0.0 0.0 0.0005" rpy="0.0 0.0 0.0"/>
            </visual>
        </link>
        <joint name="joint_${suffix}" type="revolute">
            <origin xyz="0.0 0.0 0.0" rpy="0.0 0.0 0.0"/>
            <parent link="aux_link${suffix}"/>
            <child link="link_${suffix}"/>
            <xacro:if value="${Axis == 1}">
                <axis xyz="1.0 0.0 0.0"/>
            </xacro:if>
            <xacro:if value="${Axis == 0}">
                <axis xyz="0.0 0.0 1.0"/>
            </xacro:if>
            <limit lower="${low_limit}" upper="${up_limit}" effort="${effort_value}" velocity="${speed_value}"/>
        </joint>
        
        <link name="link_${suffix}">
            <inertial>
                <origin xyz="${origin_xyz}" rpy="0.0 0.0 0.0"/>
                <mass value="${mass}"/>
                <inertia ixx="${ixx}" ixy="0.0" ixz="0.0" iyy="${iyy}" iyz="0.0" izz="${izz}"/>
            </inertial>
            <visual>
                <origin xyz="${origin_xyz}" rpy="0.0 0.0 0.0"/>
                <geometry>
                    <mesh filename="${meshfile}" scale="${1.0/meshscale} ${1.0/meshscale} ${1.0/meshscale}"/>
                </geometry>
                <material name="${color}"/>
            </visual>
            <collision>
                <origin xyz="${origin_xyz}" rpy="0.0 0.0 0.0"/>
                <geometry>
                    <mesh filename="${meshfile}" scale="${1.0/meshscale} ${1.0/meshscale} ${1.0/meshscale}"/>
                </geometry>
            </collision>
        </link>

        <transmission name="tran_${suffix}">
            <type>transmission_interface/SimpleTransmission</type>
            <joint name="joint_${suffix}">
                <hardwareInterface>hardware_interface/PositionJointInterface</hardwareInterface>
            </joint>
            <actuator name="motor_${suffix}">
                <hardwareInterface>hardware_interface/PositionJointInterface</hardwareInterface>
                <mechanicalReduction>1</mechanicalReduction>
            </actuator>
        </transmission>
      
  </xacro:macro>
  
  <link name="world"/>
  <joint name="fixed" type="fixed">
    <parent link="world"/>
    <child link="base_link"/>
  </joint>
  <link name="base_link">
      
        <inertial>
            <origin xyz="${origin_base_xyz}" rpy="0.0 0.0 0.0"/>
            <mass value="1.05"/>
            <inertia ixx="1.01" ixy="0.0" ixz="0.0" iyy="1.01" iyz="0.0" izz="1.01"/>
        </inertial>
       <visual>
          <origin xyz="${origin_base_xyz}" rpy="0.0 0.0 0.0"/>
          <geometry>
              <mesh filename="package://tutorial_urdf/meshes/robots/arm/base_arm.stl" scale="${1.0/scale} ${1.0/scale} ${1.0/scale}"/>
          </geometry>
          <material name="white"/>
      </visual>
      <collision>
          <origin xyz="${origin_base_xyz}" rpy="0.0 0.0 0.0"/>
          <geometry>
              <mesh filename="package://tutorial_urdf/meshes/robots/arm/base_arm.stl" scale="${1.0/scale} ${1.0/scale} ${1.0/scale}"/>
          </geometry>
      </collision>
  </link>
 
 <xacro:mesh_link suffix="1" parent_link="base_link" 
 origin_xyz="${origin_link1_xyz}"  Joint_xyz="${joint1_xyz}"
 meshfile="package://tutorial_urdf/meshes/robots/arm/arm_link1.stl"  meshscale="${scale}"
 mass="${mass}" ixx="${1 + 7.70/scale}" iyy="${1 + 11.59/scale}" izz="${1 + 7.80/scale}"
 Axis="0" color="green"/>
 
 <xacro:mesh_link suffix="2" parent_link="link_1" 
 origin_xyz="${origin_link2_xyz}"  Joint_xyz="${joint2_xyz}"
 meshfile="package://tutorial_urdf/meshes/robots/arm/arm_link2.stl"  meshscale="${scale}"
 mass="${mass}" ixx="${1 + 30.06/scale}" iyy="${1 + 33.13/scale}" izz="${1 + 9.32/scale}"
 Axis="1" color="blue"/>

 <xacro:mesh_link suffix="3" parent_link="link_2" 
 origin_xyz="${origin_link3_xyz}"  Joint_xyz="${joint3_xyz}"
 meshfile="package://tutorial_urdf/meshes/robots/arm/arm_link3.stl"  meshscale="${scale}"
 mass="${mass}" ixx="${1 + 10.76/scale}" iyy="${1 + 11.98/scale}" izz="${1 + 7.47/scale}"
 Axis="1" color="red"/>

<xacro:mesh_link suffix="4" parent_link="link_3" 
 origin_xyz="${origin_link4_xyz}"  Joint_xyz="${joint4_xyz}"
 meshfile="package://tutorial_urdf/meshes/robots/arm/arm_link4.stl"  meshscale="${scale}"
 mass="${mass}" ixx="${1 + 26.59/scale}" iyy="${1 + 9.94/scale}" izz="${1 + 29.03/scale}"
 Axis="0" color="white"/>

 <xacro:mesh_link suffix="5" parent_link="link_4" 
 origin_xyz="${origin_link5_xyz}"  Joint_xyz="${joint5_xyz}"
 meshfile="package://tutorial_urdf/meshes/robots/arm/arm_link5.stl"  meshscale="${scale}"
 mass="${mass}" ixx="${1 + 29.66/scale}" iyy="${1 + 9.32/scale}" izz="${1 + 32.73/scale}"
 Axis="1" color="green"/>

 <xacro:mesh_link suffix="6" parent_link="link_5" 
 origin_xyz="${origin_link6_xyz}"  Joint_xyz="${joint6_xyz}"
 meshfile="package://tutorial_urdf/meshes/robots/arm/arm_link6.stl"  meshscale="${scale}"
 mass="0.09" ixx="${1 + 59.62/scale}" iyy="${1 + 12.57/scale}" izz="${1 + 60.81/scale}"
 Axis="1" color="blue"/>

</robot>
